<?xml version="1.0" ?>
<!-- =================================================================================== -->
<!-- |    This document was autogenerated by xacro from conveyor.urdf.xacro            | -->
<!-- |    EDITING THIS FILE BY HAND IS NOT RECOMMENDED                                 | -->
<!-- =================================================================================== -->
<robot name="conveyor" xmlns:xacro="http://ros.org/wiki/xacro">
  <gazebo>
    <plugin filename="libgazebo_ros_control.so" name="gazebo_ros_control">
      <robotNamespace>/conveyor</robotNamespace>
    </plugin>
  </gazebo>
  <link name="world"/>
  <link name="conveyor_link_1">
    <visual>
      <origin rpy="0 0 0" xyz="2.5 0 0"/>
      <geometry>
        <box size="5.0 0.67 0.05"/>
      </geometry>
      <material name="Black">
        <color rgba="0 0.0 0.0 1.0"/>
      </material>
    </visual>
    <collision>
      <origin rpy="0 0 0" xyz="2.5 0 0"/>
      <geometry>
        <box size="5.0 0.67 0.05"/>
      </geometry>
    </collision>
    <inertial>
      <mass value="100.0"/>
      <inertia ixx="3.76166666667" ixy="0.0" ixz="0.0" iyy="208.354166667" iyz="0.0" izz="212.074166667"/>
    </inertial>
  </link>
  <gazebo reference="conveyor_link_1">
    <material>Gazebo/Black</material>
    <mu1>1000.0</mu1>
    <mu2>1000.0</mu2>
  </gazebo>
  <link name="conveyor_link_2">
    <visual>
      <origin rpy="0 0 0" xyz="2.5 0 0"/>
      <geometry>
        <box size="5.0 0.67 0.05"/>
      </geometry>
      <material name="Black">
        <color rgba="0 0.0 0.0 1.0"/>
      </material>
    </visual>
    <collision>
      <origin rpy="0 0 0" xyz="2.5 0 0"/>
      <geometry>
        <box size="5.0 0.67 0.05"/>
      </geometry>
    </collision>
    <inertial>
      <mass value="100.0"/>
      <inertia ixx="3.76166666667" ixy="0.0" ixz="0.0" iyy="208.354166667" iyz="0.0" izz="212.074166667"/>
    </inertial>
  </link>
  <link name="box_1">
    <inertial>
      <origin xyz="-1.85 0.5 0.575"/>
      <mass value="1"/>
      <inertia ixx="1" ixy="0.0" ixz="0.0" iyy="1" iyz="0.0" izz="1"/>
    </inertial>
    <visual>
      <origin xyz="-1.85 0.5 0.575"/>
      <geometry>
        <box size="0.15 0.15 0.15"/>
      </geometry>
    </visual>
    <collision>
      <origin xyz="-1.85 0.5 0.575"/>
      <geometry>
        <box size="0.15 0.15 0.15"/>
      </geometry>
    </collision>
  </link>
  <gazebo reference="conveyor_link_2">
    <material>Gazebo/Black</material>
    <mu1>1000.0</mu1>
    <mu2>1000.0</mu2>
  </gazebo>
  <joint name="world_conveyor_joint" type="fixed">
    <origin rpy="0.0 0.0 0.0" xyz="-2.0 0.5 0.5"/>
    <parent link="world"/>
    <child link="conveyor_link_1"/>
    <axis xyz="-2.0 0.5 0"/>
    <limit effort="10000" lower="-5.0" upper="5.0" velocity="1000"/>
    <!--<dynamics damping="100.0" />-->
  </joint>
  <joint name="conveyor_joint" type="prismatic">
    <origin rpy="0.0 0.0 1.57" xyz="5.0 -0.335 0.5"/>
    <parent link="conveyor_link_1"/>
    <child link="conveyor_link_2"/>
    <axis xyz="5.0 -0.335 0.5"/>
    <limit effort="10000" lower="-5.0" upper="5.0" velocity="1000"/>
    <!--<dynamics damping="100.0" />-->
  </joint>
</robot>
