<?xml version="1.0"?>
<robot xmlns:sensor="http://playerstage.sourceforge.net/gazebo/xmlschema/#sensor" 
   xmlns:controller="http://playerstage.sourceforge.net/gazebo/xmlschema/#controller" 
   xmlns:interface="http://playerstage.sourceforge.net/gazebo/xmlschema/#interface" 
   xmlns:xacro="http://ros.org/wiki/xacro" name="egp_40">


   <xacro:macro name="cylinder_inertia" params="m r h">
      <inertia ixx="${m*(3*r*r+h*h)/12}" ixy = "0" ixz = "0" iyy="${m*(3*r*r+h*h)/12}" iyz = "0" izz="${m*r*r/2}" />
   </xacro:macro>

   <xacro:macro name="default_transmission" params="jname">
    <transmission name="${jname}_trans">
      <type>transmission_interface/SimpleTransmission</type>
      <joint name="${jname}_joint">
        <hardwareInterface>hardware_interface/EffortJointInterface</hardwareInterface>
        <!--<hardwareInterface>hardware_interface/PositionJointInterface</hardwareInterface>
        <hardwareInterface>hardware_interface/VelocityJointInterface</hardwareInterface>-->
      </joint>
      <actuator name="${jname}_motor">
        <mechanicalReduction>1</mechanicalReduction>
      </actuator>
    </transmission>
  </xacro:macro>

   <xacro:macro name="niryo_gripper_1" params="prefix parent *origin">

      <joint name="${prefix}base_joint" type="fixed">
         <xacro:insert_block name="origin"/>
         <parent link="${parent}"/>
         <child link="${prefix}base_link"/>
      </joint>

      <!-- BASE LINK -->
      <link name="${prefix}base_link">
         <inertial>
            <mass value="0.25" />
            <origin xyz="0 0 0" />
            <cylinder_inertia m="0.20" r="0.05" h="0.05" />
         </inertial>

         <visual>
            <origin xyz="0.0 0 0" rpy="0 3.14 3.14" />
            <geometry>
               <mesh filename="package://niryo_one_description/meshes/v2/stl/G1_MainSupport.STL" scale="0.001 0.001 0.001"/>
            </geometry>
            <material name="black">
  		<color rgba="0.0 0.0 0.0 1.0"/>
            </material>
         </visual>

         <collision>
            <origin xyz="0.0 0 0" rpy="0 3.14 3.14" />
            <geometry>
               <mesh filename="package://niryo_one_description/meshes/v2/stl/G1_MainSupport.STL" scale="0.001 0.001 0.001"/>
            </geometry>
         </collision>
      </link>

      <gazebo reference="${prefix}base_link">
         <material>Gazebo/Black</material>
         <turnGravityOff>false</turnGravityOff>
      </gazebo>

      <!-- SERVO LINK -->
      <joint name="${prefix}servo_joint" type="fixed">
         <parent link="${prefix}base_link"/>
         <child link="${prefix}servo_link"/>
         <origin xyz="0 0.001 0" rpy="0.79 0 -1.57" />
         <axis xyz="-1 0 0" />
         <limit effort="10" lower="0.001" upper="0.015" velocity="0.041"/>
      </joint>
      

      <link name="${prefix}servo_link">
         <inertial>
            <mass value="0.25" />
            <origin xyz="0 0 0" />
            <cylinder_inertia m="0.20" r="0.05" h="0.05" />
         </inertial>

         <visual>
            <origin xyz="0.0 0 0" rpy="0 0 0" />
            <geometry>
               <mesh filename="package://niryo_one_description/meshes/v2/stl/G1_ServoHead.STL" scale="0.001 0.001 0.001"/>
            </geometry>

            <material name="black">
  		<color rgba="0.0 0.0 0.0 1.0"/>
            </material>
         </visual>

         <collision>
            <origin xyz="0.0 0 0" rpy="0 0 0" />
            <geometry>
               <mesh filename="package://niryo_one_description/meshes/v2/stl/G1_ServoHead.STL" scale="0.001 0.001 0.001"/>
            </geometry>
         </collision>
      </link>

      <gazebo reference="${prefix}servo_link">
         <material>Gazebo/Black</material>
         <turnGravityOff>false</turnGravityOff>
      </gazebo>

      <!-- GRIPPER ROD LEFT -->
      <joint name="${prefix}left_finger_base_joint" type="fixed">
         <parent link="${prefix}servo_link"/>
         <child link="${prefix}left_finger_base_link"/>
         <origin xyz="-0.004 -0.016 0.019" rpy="0 -0.0 1.57" />
      </joint>


      <link name="${prefix}left_finger_base_link">
         <inertial>
            <mass value="0.02" />
            <origin xyz="0 0 0" />
            <cylinder_inertia m="0.02" r="0.01" h="0.01" />
         </inertial>

         <visual>
            <origin xyz="0.0 0 0" rpy="0 0 0" />
            <geometry>
               <mesh filename="package://niryo_one_description/meshes/v2/stl/G1_Rod.STL" scale="0.001 0.001 0.001"/>
            </geometry>
            <material name="black">
  		<color rgba="0.0 0.0 0.0 1.0"/>
            </material>
         </visual>

         <collision>
            <origin xyz="0.0 0 0" rpy="0 0 0" />
            <geometry>
               <mesh filename="package://niryo_one_description/meshes/v2/stl/G1_Rod.STL" scale="0.001 0.001 0.001"/>
            </geometry>
         </collision>
      </link>

      <!-- GRIPPER CLAMP LEFT -->

      <joint name="${prefix}left_finger_joint" type="prismatic">
         <parent link="${prefix}base_link"/>
         <child link="${prefix}left_finger_link"/>
         <origin xyz="0.028 -0.017 0.019" rpy="3.14 0 3.14" />
         <axis xyz="-1 0 0" />
         <limit effort="10" lower="-0.015" upper="-0.001" velocity="0.041"/>
      </joint>
      
      <gazebo reference="${prefix}left_finger_joint">
        <implicitSpringDamper>1</implicitSpringDamper>
      </gazebo>


      <link name="${prefix}left_finger_link">
         <inertial>
            <mass value="0.02" />
            <origin xyz="0 0 0" />
            <cylinder_inertia m="0.02" r="0.01" h="0.01" />
         </inertial>

         <visual>
            <origin xyz="0.0 0 0" rpy="0 0 0" />
            <geometry>
               <mesh filename="package://niryo_one_description/meshes/v2/stl/G1_ClampLeft.STL" scale="0.001 0.001 0.001"/>
            </geometry>
            <material name="grey">
  		<color rgba="0.5 0.5 0.5 1"/>
            </material>
         </visual>

         <collision>
            <origin xyz="0.0 0 0" rpy="0 0 0" />
            <geometry>
               <mesh filename="package://niryo_one_description/meshes/v2/stl/G1_ClampLeft.STL" scale="0.001 0.001 0.001"/>
            </geometry>
         </collision>
      </link>
      


      <!-- GRIPPER ROD RIGHT -->
      <joint name="${prefix}right_finger_base_joint" type="fixed">
         <parent link="${prefix}servo_link"/>
         <child link="${prefix}right_finger_base_link"/>
         <origin xyz="-0.007 0.008 -0.00" rpy="0 0.96 -1.57" />
      </joint>
      
     

      <link name="${prefix}right_finger_base_link">
         <inertial>
            <mass value="0.02" />
            <origin xyz="0 0 0" />
            <cylinder_inertia m="0.02" r="0.01" h="0.01" />
         </inertial>

         <visual>
            <origin xyz="0.0 0 0" rpy="0 0 0" />
            <geometry>
               <mesh filename="package://niryo_one_description/meshes/v2/stl/G1_Rod.STL" scale="0.001 0.001 0.001"/>
            </geometry>
            <material name="black">
  		<color rgba="0.0 0.0 0.0 1.0"/>
            </material>
         </visual>

         <collision>
            <origin xyz="0.0 0 0" rpy="0 0 0" />
            <geometry>
               <mesh filename="package://niryo_one_description/meshes/v2/stl/G1_Rod.STL" scale="0.001 0.001 0.001"/>
            </geometry>
         </collision>
      </link>

      <!-- GRIPPER CLAMP RIGHT -->

      <joint name="${prefix}right_finger_joint" type="prismatic">
         <parent link="${prefix}base_link"/>
         <child link="${prefix}right_finger_link"/>
         <origin xyz="0.003 -0.017 0.019" rpy="3.14 0 3.14" />         
	 <axis xyz="-1 0 0" />
         <limit effort="10" lower="0.001" upper="0.015" velocity="0.041"/>
      </joint>
      
      <gazebo reference="${prefix}right_finger_joint">
        <implicitSpringDamper>1</implicitSpringDamper>
      </gazebo>

      <link name="${prefix}right_finger_link">
         <inertial>
            <mass value="0.02" />
            <origin xyz="0 0 0" />
            <cylinder_inertia m="0.02" r="0.01" h="0.01" />
         </inertial>

         <visual>
            <origin xyz="0.0 0 0" rpy="0 0 0" />
            <geometry>
               <mesh filename="package://niryo_one_description/meshes/v2/stl/G1_ClampRight.STL" scale="0.001 0.001 0.001"/>
            </geometry>
            <material name="grey">
               <color rgba="0.5 0.5 0.5 1"/>
            </material>
         </visual>

         <collision>
            <origin xyz="0.0 0 0" rpy="0 0 0" />
            <geometry>
               <mesh filename="package://niryo_one_description/meshes/v2/stl/G1_ClampRight.STL" scale="0.001 0.001 0.001"/>
            </geometry>
         </collision>
      </link>
  
    <gazebo>  
    <plugin name='ft_sensor_l' filename='libgazebo_ros_ft_sensor.so'>
      <updateRate>100.0</updateRate>
      <topicName>ft_sensor_left_finger</topicName>
      <jointName>${prefix}left_finger_joint</jointName>
    </plugin>
    <static>0</static>
    <plugin name='ft_sensor_r' filename='libgazebo_ros_ft_sensor.so'>
      <updateRate>100.0</updateRate>
      <topicName>ft_sensor_right_finger</topicName>
      <jointName>${prefix}right_finger_joint</jointName>
    </plugin>
    </gazebo>

    <!-- hack from here: https://github.com/JenniferBuehler/gazebo-pkgs/wiki/The-Gazebo-grasp-fix-plugin -->
    <gazebo>
       <plugin name="gazebo_grasp_fix" filename="libgazebo_grasp_fix.so">
            <arm>
               <arm_name>niryo-arm</arm_name>
               <palm_link>hand_link</palm_link>
               <gripper_link>${prefix}left_finger_link</gripper_link>
               <gripper_link>${prefix}right_finger_link</gripper_link>
            </arm>
           <forces_angle_tolerance>100</forces_angle_tolerance>
           <update_rate>4</update_rate>
           <grip_count_threshold>4</grip_count_threshold>
           <max_grip_count>8</max_grip_count>
           <release_tolerance>0.005</release_tolerance>
           <disable_collisions_on_attach>false</disable_collisions_on_attach>
           <contact_topic>__default_topic__</contact_topic>
        </plugin>
    </gazebo>
   
    <xacro:default_transmission jname="${prefix}left_finger"/>
    <xacro:default_transmission jname="${prefix}right_finger"/>  

   </xacro:macro>

</robot>

